<?xml version="1.0"?>
<robot xmlns:sensor="http://playerstage.sourceforge.net/gazebo/xmlschema/#sensor"
       xmlns:controller="http://playerstage.sourceforge.net/gazebo/xmlschema/#controller"
       xmlns:interface="http://playerstage.sourceforge.net/gazebo/xmlschema/#interface"
       xmlns:xacro="http://ros.org/wiki/xacro">

  <xacro:include filename="$(find ahl_youbot_description)/urdf/gripper/gripper.gazebo.xacro"/>
  <xacro:include filename="$(find ahl_youbot_description)/urdf/gripper/gripper.transmission.xacro"/>
  <xacro:include filename="$(find ahl_youbot_description)/urdf/gripper/limits.urdf"/>

  <xacro:macro name="youbot_gripper" params="name">

    <joint name="finger_joint_l" type="prismatic">
      <parent link="link5"/>
      <child link="finger_link_l"/>
      <origin xyz="0 0.0082 0.095" rpy="0 0 0"/>
      <axis xyz="0 1 0"/>
      <dynamics damping="1.0" friction="0"/>
      <limit effort="10000" velocity="0.1" lower="0" upper="${finger_joint}"/>
    </joint>

    <link name="finger_link_l">
      <inertial>
        <origin xyz="0.000270 -0.001337 0.020234" rpy="0 0 0"/>
        <mass value="0.01"/>
        <inertia ixx="0.000005" ixy="0" ixz="0" iyy="0.000005" iyz="0" izz="0.000005"/>
      </inertial>
      <visual>
        <origin xyz="0 0 0.0121" rpy="0 0 ${M_PI}"/>
        <geometry>
          <mesh filename="package://ahl_youbot_description/meshes/gripper/finger.dae"/>
        </geometry>
      </visual>
      <collision>
        <origin xyz="0 0 0.0121" rpy="0 0 ${M_PI}"/>
        <geometry>
          <mesh filename="package://ahl_youbot_description/meshes/gripper/finger_convex.stl"/>
        </geometry>
      </collision>
    </link>

    <joint name="finger_joint_r" type="prismatic">
      <parent link="link5"/>
      <child link="finger_link_r"/>
      <origin xyz="0 -0.0082 0.095" rpy="0 0 0"/>
      <axis xyz="0 1 0"/>
      <dynamics damping="1.0" friction="0"/>
      <limit effort="10000" velocity="0.1" lower="-${finger_joint}" upper="0"/> 
    </joint>

    <link name="finger_link_r">
      <inertial>
        <origin xyz="0.000270 -0.001337 0.020234" rpy="0 0 0"/>
        <mass value="0.01"/>
        <inertia ixx="0.000005" ixy="0" ixz="0" iyy="0.000005" iyz="0" izz="0.000005"/>
      </inertial>
      <visual>
        <origin xyz="0 0 0.0121" rpy="0 0 0"/>
        <geometry>
          <mesh filename="package://ahl_youbot_description/meshes/gripper/finger.dae"/>
        </geometry>
      </visual>
      <collision>
        <origin xyz="0 0 0.0121" rpy="0 0 0"/>
        <geometry>
          <mesh filename="package://ahl_youbot_description/meshes/gripper/finger_convex.stl"/>
        </geometry>
      </collision>
    </link>

    <!-- extensions -->
    <xacro:youbot_gripper_gazebo name="${name}"/>
    <xacro:youbot_gripper_transmission name="${name}"/>

  </xacro:macro>
</robot>
