<?xml version="1.0" ?>
<sdf version="1.5">
  <model name="youbot">
    <link name="base_footprint">
      <pose>0 0 0 0 0 0</pose>
      <inertial>
        <pose>0 0 -0.050000 0 0 0</pose>
        <inertia>
          <ixx>0</ixx>
          <ixy>0</ixy>
          <ixz>0</ixz>
          <iyy>0</iyy>
          <iyz>0</iyz>
          <izz>0</izz>
        </inertia>
        <mass>0.1</mass>
      </inertial>
      <collision name="base_footprint_geom">
        <pose>0 0 -0.050000 0 0 0</pose>
        <geometry>
          <box>
            <size>0 0 0</size>
          </box>
        </geometry>
        <surface>
          <friction>
            <ode>
              <mu>0</mu>
              <mu2>0</mu2>
              <fdir1>0 0 0</fdir1>
              <slip1>0</slip1>
              <slip2>0</slip2>
            </ode>
          </friction>
          <bounce>
            <restitution_coefficient>0</restitution_coefficient>
            <threshold>0</threshold>
          </bounce>
          <contact>
            <ode>
              <soft_cfm>0</soft_cfm>
              <soft_erp>0.200000</soft_erp>
              <kp>10000000000000.000000</kp>
              <kd>100000000000.000000</kd>
              <max_vel>-1</max_vel>
              <min_depth>0</min_depth>
            </ode>
          </contact>
        </surface>
        <laser_retro>0</laser_retro>
      </collision>
      <visual name="base_footprint_geom_visual">
        <pose>0 0 0 0 0 0</pose>
        <geometry>
          <box>
            <size>0 0 0</size>
          </box>
        </geometry>
      </visual>
      <gravity>1</gravity>
      <self_collide>0</self_collide>
      <kinematic>0</kinematic>
    </link>
    <link name="base_link">
      <pose>0 0 0.096300 0 0 0</pose>
      <inertial>
        <pose>-0.001408 0.000569 -0.024801 0 0 0</pose>
        <inertia>
          <ixx>0.227239</ixx>
          <ixy>0</ixy>
          <ixz>0</ixz>
          <iyy>0.476922</iyy>
          <iyz>0</iyz>
          <izz>0.677428</izz>
        </inertia>
        <mass>19.803000</mass>
      </inertial>
      <collision name="base_link_geom">
        <pose>0 0 0 0 0 0</pose>
        <geometry>
          <mesh>
            <uri>model://youbot/meshes/base/base_convex.stl</uri>
          </mesh>
        </geometry>
        <surface>
          <friction>
            <ode>
              <mu>0</mu>
              <mu2>0</mu2>
              <fdir1>0 0 0</fdir1>
              <slip1>0</slip1>
              <slip2>0</slip2>
            </ode>
          </friction>
          <bounce>
            <restitution_coefficient>0</restitution_coefficient>
            <threshold>0</threshold>
          </bounce>
          <contact>
            <ode>
              <soft_cfm>0</soft_cfm>
              <soft_erp>0.200000</soft_erp>
              <kp>10000000000000.000000</kp>
              <kd>100000000000.000000</kd>
              <max_vel>-1</max_vel>
              <min_depth>0</min_depth>
            </ode>
          </contact>
        </surface>
        <laser_retro>0</laser_retro>
      </collision>
      <visual name="base_link_geom_visual">
        <pose>0 0 0 0 0 0</pose>
        <geometry>
          <mesh>
            <uri>model://youbot/meshes/base/base.dae</uri>
          </mesh>
        </geometry>
      </visual>
      <gravity>1</gravity>
      <self_collide>0</self_collide>
      <kinematic>0</kinematic>
    </link>
    <link name="arm_link_0">
      <pose>0.143000 0 0.117000 0 0 0</pose>
      <inertial>
        <pose>0.015221 -0.000041 0.033843 0 0 0</pose>
        <inertia>
          <ixx>0.001875</ixx>
          <ixy>0</ixy>
          <ixz>0</ixz>
          <iyy>0.001875</iyy>
          <iyz>0</iyz>
          <izz>0.002775</izz>
        </inertia>
        <mass>0.961000</mass>
      </inertial>
      <collision name="arm_link_0_geom">
        <pose>0 0 0.031800 0 0 0</pose>
        <geometry>
          <mesh>
            <uri>model://youbot/meshes/arm/arm0_convex.stl</uri>
          </mesh>
        </geometry>
        <surface>
          <friction>
            <ode>
              <mu>0</mu>
              <mu2>0</mu2>
              <fdir1>0 0 0</fdir1>
              <slip1>0</slip1>
              <slip2>0</slip2>
            </ode>
          </friction>
          <bounce>
            <restitution_coefficient>0</restitution_coefficient>
            <threshold>0</threshold>
          </bounce>
          <contact>
            <ode>
              <soft_cfm>0</soft_cfm>
              <soft_erp>0.200000</soft_erp>
              <kp>10000000000000.000000</kp>
              <kd>100000000000.000000</kd>
              <max_vel>-1</max_vel>
              <min_depth>0</min_depth>
            </ode>
          </contact>
        </surface>
        <laser_retro>0</laser_retro>
      </collision>
      <visual name="arm_link_0_geom_visual">
        <pose>0 0 0.031800 0 0 0</pose>
        <geometry>
          <mesh>
            <uri>model://youbot/meshes/arm/arm0.dae</uri>
          </mesh>
        </geometry>
      </visual>
      <gravity>1</gravity>
      <self_collide>1</self_collide>
      <kinematic>0</kinematic>
    </link>
    <link name="arm_link_1">
      <pose>0.167000 0 0.194 0 0 0</pose>
      <inertial>
        <pose>-0.010838 0.006337 0.034345 0 0 0</pose>
        <inertia>
          <ixx>0.003003</ixx>
          <ixy>0</ixy>
          <ixz>0</ixz>
          <iyy>0.003003</iyy>
          <iyz>0</iyz>
          <izz>0.004904</izz>
        </inertia>
        <mass>1.390000</mass>
      </inertial>
      <collision name="arm_link_1_geom">
        <pose>0 0 0.0499 0 0 0</pose>
        <geometry>
          <mesh>
            <uri>model://youbot/meshes/arm/arm1_convex.stl</uri>
          </mesh>
        </geometry>
        <surface>
          <friction>
            <ode>
              <mu>0</mu>
              <mu2>0</mu2>
              <fdir1>0 0 0</fdir1>
              <slip1>0</slip1>
              <slip2>0</slip2>
            </ode>
          </friction>
          <bounce>
            <restitution_coefficient>0</restitution_coefficient>
            <threshold>0</threshold>
          </bounce>
          <contact>
            <ode>
              <soft_cfm>0</soft_cfm>
              <soft_erp>0.200000</soft_erp>
              <kp>10000000000000.000000</kp>
              <kd>100000000000.000000</kd>
              <max_vel>-1</max_vel>
              <min_depth>0</min_depth>
            </ode>
          </contact>
        </surface>
        <laser_retro>0</laser_retro>
      </collision>
      <visual name="arm_link_1_geom_visual">
        <pose>0 0 0.0499 0 0 0</pose>
        <geometry>
          <mesh>
            <uri>model://youbot/meshes/arm/arm1.dae</uri>
          </mesh>
        </geometry>
      </visual>
      <gravity>1</gravity>
      <self_collide>1</self_collide>
      <kinematic>0</kinematic>
    </link>
    <link name="arm_link_2">
      <pose>0.20000 0 0.264000 0 0 0</pose>
      <inertial>
        <pose>0.001377 -0.029369 0.086325 0 0 0</pose>
        <inertia>
          <ixx>0.0031163</ixx>
          <ixy>0</ixy>
          <ixz>0</ixz>
          <iyy>0.003115</iyy>
          <iyz>0</iyz>
          <izz>0.000584</izz>
        </inertia>
        <mass>1.318000</mass>
      </inertial>
      <collision name="arm_link_2_geom">
        <pose>0 -0.032000 0.078000 0 0 0</pose>
        <geometry>
          <mesh>
            <uri>model://youbot/meshes/arm/arm2_convex.stl</uri>
          </mesh>
        </geometry>
        <surface>
          <friction>
            <ode>
              <mu>0</mu>
              <mu2>0</mu2>
              <fdir1>0 0 0</fdir1>
              <slip1>0</slip1>
              <slip2>0</slip2>
            </ode>
          </friction>
          <bounce>
            <restitution_coefficient>0</restitution_coefficient>
            <threshold>0</threshold>
          </bounce>
          <contact>
            <ode>
              <soft_cfm>0</soft_cfm>
              <soft_erp>0.200000</soft_erp>
              <kp>10000000000000.000000</kp>
              <kd>100000000000.000000</kd>
              <max_vel>-1</max_vel>
              <min_depth>0</min_depth>
            </ode>
          </contact>
        </surface>
        <laser_retro>0</laser_retro>
      </collision>
      <visual name="arm_link_2_geom_visual">
        <pose>0 -0.032000 0.078000 0 0 0</pose>
        <geometry>
          <mesh>
            <uri>model://youbot/meshes/arm/arm2.dae</uri>
          </mesh>
        </geometry>
      </visual>
      <gravity>1</gravity>
      <self_collide>1</self_collide>
      <kinematic>0</kinematic>
    </link>
    <link name="arm_link_3">
      <pose>0.200000 0 0.419000 0 0 0</pose>
      <inertial>
        <pose>0.000130 0.028500 0.079400 0 0 0</pose>
        <inertia>
          <ixx>0.001847</ixx>
          <ixy>0</ixy>
          <ixz>0</ixz>
          <iyy>0.001728</iyy>
          <iyz>0</iyz>
          <izz>0.000584</izz>
        </inertia>
        <mass>0.821000</mass>
      </inertial>
      <collision name="arm_link_3_geom">
        <pose>0 0.028000 0.079000 0 0 0</pose>
        <geometry>
          <mesh>
            <uri>model://youbot/meshes/arm/arm3_convex.stl</uri>
          </mesh>
        </geometry>
        <surface>
          <friction>
            <ode>
              <mu>0</mu>
              <mu2>0</mu2>
              <fdir1>0 0 0</fdir1>
              <slip1>0</slip1>
              <slip2>0</slip2>
            </ode>
          </friction>
          <bounce>
            <restitution_coefficient>0</restitution_coefficient>
            <threshold>0</threshold>
          </bounce>
          <contact>
            <ode>
              <soft_cfm>0</soft_cfm>
              <soft_erp>0.200000</soft_erp>
              <kp>10000000000000.000000</kp>
              <kd>100000000000.000000</kd>
              <max_vel>-1</max_vel>
              <min_depth>0</min_depth>
            </ode>
          </contact>
        </surface>
        <laser_retro>0</laser_retro>
      </collision>
      <visual name="arm_link_3_geom_visual">
        <pose>0 0.028000 0.079000 0 0 0</pose>
        <geometry>
          <mesh>
            <uri>model://youbot/meshes/arm/arm3.dae</uri>
          </mesh>
        </geometry>
      </visual>
      <gravity>1</gravity>
      <self_collide>1</self_collide>
      <kinematic>0</kinematic>
    </link>
    <link name="arm_link_4">
      <pose>0.200000 0 0.554000 0 0 0</pose>
      <inertial>
        <pose>0.000124 -0.005595 0.040469 0 0 0</pose>
        <inertia>
          <ixx>0.001057</ixx>
          <ixy>0</ixy>
          <ixz>0</ixz>
          <iyy>0.000676</iyy>
          <iyz>0</iyz>
          <izz>0.000661</izz>
        </inertia>
        <mass>0.769000</mass>
      </inertial>
      <collision name="arm_link_4_geom">
        <pose>0 -0.010000 0.029000 0 0 0</pose>
        <geometry>
          <mesh>
            <uri>model://youbot/meshes/arm/arm4_convex.stl</uri>
          </mesh>
        </geometry>
        <surface>
          <friction>
            <ode>
              <mu>0</mu>
              <mu2>0</mu2>
              <fdir1>0 0 0</fdir1>
              <slip1>0</slip1>
              <slip2>0</slip2>
            </ode>
          </friction>
          <bounce>
            <restitution_coefficient>0</restitution_coefficient>
            <threshold>0</threshold>
          </bounce>
          <contact>
            <ode>
              <soft_cfm>0</soft_cfm>
              <soft_erp>0.200000</soft_erp>
              <kp>10000000000000.000000</kp>
              <kd>100000000000.000000</kd>
              <max_vel>-1</max_vel>
              <min_depth>0</min_depth>
            </ode>
          </contact>
        </surface>
        <laser_retro>0</laser_retro>
      </collision>
      <visual name="arm_link_4_geom_visual">
        <pose>0 -0.010000 0.029000 0 0 0</pose>
        <geometry>
          <mesh>
            <uri>model://youbot/meshes/arm/arm4.dae</uri>
          </mesh>
        </geometry>
      </visual>
      <gravity>1</gravity>
      <self_collide>1</self_collide>
      <kinematic>0</kinematic>
    </link>
    <link name="arm_link_5">
      <pose>0.200000 0 0.638000 0 0 0</pose>
      <inertial>
        <pose>-0.000903 0.000638 0.006573 0 0 0</pose>
        <inertia>
          <ixx>0.000160</ixx>
          <ixy>0</ixy>
          <ixz>0</ixz>
          <iyy>0.000069</iyy>
          <iyz>0</iyz>
          <izz>0.000193</izz>
        </inertia>
        <mass>0.687000</mass>
      </inertial>
      <collision name="arm_link_5_geom">
        <pose>0 0 0.018800 0 0 0</pose>
        <geometry>
          <mesh>
            <uri>model://youbot/meshes/arm/arm5_convex.stl</uri>
          </mesh>
        </geometry>
        <surface>
          <friction>
            <ode>
              <mu>0</mu>
              <mu2>0</mu2>
              <fdir1>0 0 0</fdir1>
              <slip1>0</slip1>
              <slip2>0</slip2>
            </ode>
          </friction>
          <bounce>
            <restitution_coefficient>0</restitution_coefficient>
            <threshold>0</threshold>
          </bounce>
          <contact>
            <ode>
              <soft_cfm>0</soft_cfm>
              <soft_erp>0.200000</soft_erp>
              <kp>10000000000000.000000</kp>
              <kd>100000000000.000000</kd>
              <max_vel>-1</max_vel>
              <min_depth>0</min_depth>
            </ode>
          </contact>
        </surface>
        <laser_retro>0</laser_retro>
      </collision>
      <visual name="arm_link_5_geom_visual">
        <pose>0 0 0.018800 0 0 0</pose>
        <geometry>
          <mesh>
            <uri>model://youbot/meshes/arm/arm5.dae</uri>
          </mesh>
        </geometry>
      </visual>
      <gravity>1</gravity>
      <self_collide>1</self_collide>
      <kinematic>0</kinematic>
    </link>
    <link name="gripper_palm_link">
      <pose>0.200000 0 0.678000 0 0 0</pose>
      <inertial>
        <pose>0.002737 0 0.02616 0 0 0</pose>
        <inertia>
          <ixx>0.000363</ixx>
          <ixy>0</ixy>
          <ixz>0</ixz>
          <iyy>0.000207</iyy>
          <iyz>0</iyz>
          <izz>0.000232</izz>
        </inertia>
        <mass>0.199000</mass>
      </inertial>
      <collision name="gripper_palm_link_geom">
        <pose>-0.002730 0 0.022400 0 0 0</pose>
        <geometry>
          <mesh>
            <uri>model://youbot/meshes/gripper/palm_convex.stl</uri>
          </mesh>
        </geometry>
        <surface>
          <friction>
            <ode>
              <mu>0</mu>
              <mu2>0</mu2>
              <fdir1>0 0 0</fdir1>
              <slip1>0</slip1>
              <slip2>0</slip2>
            </ode>
          </friction>
          <bounce>
            <restitution_coefficient>0</restitution_coefficient>
            <threshold>0</threshold>
          </bounce>
          <contact>
            <ode>
              <soft_cfm>0</soft_cfm>
              <soft_erp>0.200000</soft_erp>
              <kp>10000000000000.000000</kp>
              <kd>100000000000.000000</kd>
              <max_vel>-1</max_vel>
              <min_depth>0</min_depth>
            </ode>
          </contact>
        </surface>
        <laser_retro>0</laser_retro>
      </collision>
      <visual name="gripper_palm_link_geom_visual">
        <pose>-0.002730 0 0.022400 0 0 0</pose>
        <geometry>
          <mesh>
            <uri>model://youbot/meshes/gripper/palm.dae</uri>
          </mesh>
        </geometry>
      </visual>
      <gravity>1</gravity>
      <self_collide>1</self_collide>
      <kinematic>0</kinematic>
    </link>
    <link name="gripper_finger_link_l">
      <pose>0.200000 0.008200 0.733000 0 0 0</pose>
      <inertial>
        <pose>0.000270 -0.001337 0.020234 0 0 0</pose>
        <inertia>
          <ixx>0</ixx>
          <ixy>0</ixy>
          <ixz>0</ixz>
          <iyy>0</iyy>
          <iyz>0</iyz>
          <izz>0</izz>
        </inertia>
        <mass>0.010000</mass>
      </inertial>
      <collision name="gripper_finger_link_l_geom">
        <pose>0 0 0.012100 0 0 3.1415926535897932</pose>
        <geometry>
          <mesh>
            <uri>model://youbot/meshes/gripper/finger_convex.stl</uri>
          </mesh>
        </geometry>
        <surface>
          <friction>
            <ode>
              <mu>0.5</mu>
              <mu2>0</mu2>
              <fdir1>0 0 0</fdir1>
              <slip1>0</slip1>
              <slip2>0</slip2>
            </ode>
          </friction>
          <bounce>
            <restitution_coefficient>0</restitution_coefficient>
            <threshold>0</threshold>
          </bounce>
          <contact>
            <ode>
              <soft_cfm>0</soft_cfm>
              <soft_erp>0.200000</soft_erp>
              <kp>10000000000000.000000</kp>
              <kd>100000000000.000000</kd>
              <max_vel>-1</max_vel>
              <min_depth>0</min_depth>
            </ode>
          </contact>
        </surface>
        <laser_retro>0</laser_retro>
      </collision>
      <visual name="gripper_finger_link_l_geom_visual">
        <pose>0 0 0.012100 0 0 3.1415926535897932</pose>
        <geometry>
          <mesh>
            <uri>model://youbot/meshes/gripper/finger.dae</uri>
          </mesh>
        </geometry>
      </visual>
      <gravity>1</gravity>
      <self_collide>0</self_collide>
      <kinematic>0</kinematic>
    </link>
    <link name="gripper_finger_link_r">
      <pose>0.200000 -0.008200 0.733000 0 0 0</pose>
      <inertial>
        <pose>0.000270 0.001337 0.020234 0 0 0</pose>
        <inertia>
          <ixx>0</ixx>
          <ixy>0</ixy>
          <ixz>0</ixz>
          <iyy>0</iyy>
          <iyz>0</iyz>
          <izz>0</izz>
        </inertia>
        <mass>0.010000</mass>
      </inertial>
      <collision name="gripper_finger_link_r_geom">
        <pose>0 0 0.012100 0 0 0</pose>
        <geometry>
          <mesh>
            <uri>model://youbot/meshes/gripper/finger_convex.stl</uri>
          </mesh>
        </geometry>
        <surface>
          <friction>
            <ode>
              <mu>0.5</mu>
              <mu2>0</mu2>
              <fdir1>0 0 0</fdir1>
              <slip1>0</slip1>
              <slip2>0</slip2>
            </ode>
          </friction>
          <bounce>
            <restitution_coefficient>0</restitution_coefficient>
            <threshold>0</threshold>
          </bounce>
          <contact>
            <ode>
              <soft_cfm>0</soft_cfm>
              <soft_erp>0.200000</soft_erp>
              <kp>10000000000000.000000</kp>
              <kd>100000000000.000000</kd>
              <max_vel>-1</max_vel>
              <min_depth>0</min_depth>
            </ode>
          </contact>
        </surface>
        <laser_retro>0</laser_retro>
      </collision>
      <visual name="gripper_finger_link_r_geom_visual">
        <pose>0 0 0.012100 0 0 0</pose>
        <geometry>
          <mesh>
            <uri>model://youbot/meshes/gripper/finger.dae</uri>
          </mesh>
        </geometry>
      </visual>
      <gravity>1</gravity>
      <self_collide>0</self_collide>
      <kinematic>0</kinematic>
    </link>
    <link name="base_laser_front_link">
      <pose>0.300000 0 0.054000 0 0 0</pose>
      <inertial>
        <pose>0 0 0 0 0 0</pose>
        <inertia>
          <ixx>0</ixx>
          <ixy>0</ixy>
          <ixz>0</ixz>
          <iyy>0</iyy>
          <iyz>0</iyz>
          <izz>0</izz>
        </inertia>
        <mass>0.160000</mass>
      </inertial>
      <collision name="base_laser_front_link_geom">
        <pose>0 0 0 0 0 0</pose>
        <geometry>
          <mesh>
            <uri>model://hokuyo/meshes/hokuyo_convex.stl</uri>
          </mesh>
        </geometry>
        <surface>
          <friction>
            <ode>
              <mu>0</mu>
              <mu2>0</mu2>
              <fdir1>0 0 0</fdir1>
              <slip1>0</slip1>
              <slip2>0</slip2>
            </ode>
          </friction>
          <bounce>
            <restitution_coefficient>0</restitution_coefficient>
            <threshold>0</threshold>
          </bounce>
          <contact>
            <ode>
              <soft_cfm>0</soft_cfm>
              <soft_erp>0.200000</soft_erp>
              <kp>10000000000000.000000</kp>
              <kd>100000000000.000000</kd>
              <max_vel>-1</max_vel>
              <min_depth>0</min_depth>
            </ode>
          </contact>
        </surface>
        <laser_retro>0</laser_retro>
      </collision>
      <visual name="base_laser_front_link_geom_visual">
        <pose>0 0 0 0 0 0</pose>
        <geometry>
          <mesh>
            <uri>model://hokuyo/meshes/hokuyo.dae</uri>
          </mesh>
        </geometry>
      </visual>
      <sensor name="base_laser_front" type="ray">
        <pose>0 0 0 0 0 0</pose>
        <ray>
          <scan>
            <horizontal>
              <samples>640</samples>
              <resolution>1</resolution>
              <min_angle>-1.570000</min_angle>
              <max_angle>1.570000</max_angle>
            </horizontal>
          </scan>
          <range>
            <min>0.050000</min>
            <max>5.600000</max>
            <resolution>0.360000</resolution>
          </range>
        </ray>
        <always_on>0</always_on>
        <update_rate>10.000000</update_rate>
        <visualize>0</visualize>
      </sensor>
      <gravity>1</gravity>
      <self_collide>0</self_collide>
      <kinematic>0</kinematic>
    </link>
    <link name="caster_link_bl">
      <pose>-0.228000 0.158000 -0.046300 0 0 0</pose>
      <inertial>
        <pose>0 0 0 0 0 0</pose>
        <inertia>
          <ixx>0</ixx>
          <ixy>0</ixy>
          <ixz>0</ixz>
          <iyy>0</iyy>
          <iyz>0</iyz>
          <izz>0</izz>
        </inertia>
        <mass>0.100000</mass>
      </inertial>
      <gravity>1</gravity>
      <self_collide>0</self_collide>
      <kinematic>0</kinematic>
    </link>
    <link name="wheel_link_bl">
      <pose>-0.228000 0.158000 0.046300 0 0 0</pose>
      <inertial>
        <pose>0 0 0 0 0 0</pose>
        <inertia>
          <ixx>0.001480</ixx>
          <ixy>0</ixy>
          <ixz>0</ixz>
          <iyy>0.00175</iyy>
          <iyz>0</iyz>
          <izz>0.001480</izz>
        </inertia>
        <mass>1.400000</mass>
      </inertial>
      <collision name="wheel_link_bl_geom">
        <pose>0 0 0 1.570800 0 0</pose>
        <geometry>
          <cylinder>
            <radius>0.050000</radius>
            <length>0.005000</length>
          </cylinder>
        </geometry>
        <surface>
          <friction>
            <ode>
              <mu>0.5</mu>
              <mu2>0.5</mu2>
              <fdir1>1 0 0</fdir1>
              <slip1>0</slip1>
              <slip2>0</slip2>
            </ode>
          </friction>
          <bounce>
            <restitution_coefficient>0</restitution_coefficient>
            <threshold>0</threshold>
          </bounce>
          <contact>
            <ode>
              <soft_cfm>0</soft_cfm>
              <soft_erp>0.200000</soft_erp>
              <kp>10000000000000.000000</kp>
              <kd>100000000000.000000</kd>
              <max_vel>-1</max_vel>
              <min_depth>0</min_depth>
            </ode>
          </contact>
        </surface>
        <laser_retro>0</laser_retro>
      </collision>
      <visual name="wheel_link_bl_geom_visual">
        <pose>0 0 0 0 0 0</pose>
        <geometry>
          <mesh>
            <uri>model://youbot/meshes/base/back-left_wheel.dae</uri>
          </mesh>
        </geometry>
      </visual>
      <gravity>1</gravity>
      <self_collide>0</self_collide>
      <kinematic>0</kinematic>
    </link>
    <link name="caster_link_br">
      <pose>-0.228000 -0.158000 -0.046300 0 0 0</pose>
      <inertial>
        <pose>0 0 0 0 0 0</pose>
        <inertia>
          <ixx>0</ixx>
          <ixy>0</ixy>
          <ixz>0</ixz>
          <iyy>0</iyy>
          <iyz>0</iyz>
          <izz>0</izz>
        </inertia>
        <mass>0.100000</mass>
      </inertial>
      <gravity>1</gravity>
      <self_collide>0</self_collide>
      <kinematic>0</kinematic>
    </link>
    <link name="wheel_link_br">
      <pose>-0.228000 -0.158000 0.046300 0 0 0</pose>
      <inertial>
        <pose>0 0 0 0 0 0</pose>
        <inertia>
          <ixx>0.001480</ixx>
          <ixy>0</ixy>
          <ixz>0</ixz>
          <iyy>0.00175</iyy>
          <iyz>0</iyz>
          <izz>0.001480</izz>
        </inertia>
        <mass>1.400000</mass>
      </inertial>
      <collision name="wheel_link_br_geom">
        <pose>0 0 0 1.570800 0 0</pose>
        <geometry>
          <cylinder>
            <radius>0.050000</radius>
            <length>0.005000</length>
          </cylinder>
        </geometry>
        <surface>
          <friction>
            <ode>
              <mu>0.5</mu>
              <mu2>0.5</mu2>
              <fdir1>1 0 0</fdir1>
              <slip1>0</slip1>
              <slip2>0</slip2>
            </ode>
          </friction>
          <bounce>
            <restitution_coefficient>0</restitution_coefficient>
            <threshold>0</threshold>
          </bounce>
          <contact>
            <ode>
              <soft_cfm>0</soft_cfm>
              <soft_erp>0.200000</soft_erp>
              <kp>10000000000000.000000</kp>
              <kd>100000000000.000000</kd>
              <max_vel>-1</max_vel>
              <min_depth>0</min_depth>
            </ode>
          </contact>
        </surface>
        <laser_retro>0</laser_retro>
      </collision>
      <visual name="wheel_link_br_geom_visual">
        <pose>0 0 0 0 0 0</pose>
        <geometry>
          <mesh>
            <uri>model://youbot/meshes/base/back-right_wheel.dae</uri>
          </mesh>
        </geometry>
      </visual>
      <gravity>1</gravity>
      <self_collide>0</self_collide>
      <kinematic>0</kinematic>
    </link>
    <link name="caster_link_fl">
      <pose>0.228000 0.158000 -0.046300 0 0 0</pose>
      <inertial>
        <pose>0 0 0 0 0 0</pose>
        <inertia>
          <ixx>0</ixx>
          <ixy>0</ixy>
          <ixz>0</ixz>
          <iyy>0</iyy>
          <iyz>0</iyz>
          <izz>0</izz>
        </inertia>
        <mass>0.100000</mass>
      </inertial>
      <gravity>1</gravity>
      <self_collide>0</self_collide>
      <kinematic>0</kinematic>
    </link>
    <link name="wheel_link_fl">
      <pose>0.228000 0.158000 0.046300 0 0 0</pose>
      <inertial>
        <pose>0 0 0 0 0 0</pose>
        <inertia>
          <ixx>0.001480</ixx>
          <ixy>0</ixy>
          <ixz>0</ixz>
          <iyy>0.00175</iyy>
          <iyz>0</iyz>
          <izz>0.001480</izz>
        </inertia>
        <mass>1.400000</mass>
      </inertial>
      <collision name="wheel_link_fl_geom">
        <pose>0 0 0 1.570800 0 0</pose>
        <geometry>
          <cylinder>
            <radius>0.050000</radius>
            <length>0.005000</length>
          </cylinder>
        </geometry>
        <surface>
          <friction>
            <ode>
              <mu>0.5</mu>
              <mu2>0.5</mu2>
              <fdir1>1 0 0</fdir1>
              <slip1>0</slip1>
              <slip2>0</slip2>
            </ode>
          </friction>
          <bounce>
            <restitution_coefficient>0</restitution_coefficient>
            <threshold>0</threshold>
          </bounce>
          <contact>
            <ode>
              <soft_cfm>0</soft_cfm>
              <soft_erp>0.200000</soft_erp>
              <kp>10000000000000.000000</kp>
              <kd>100000000000.000000</kd>
              <max_vel>-1</max_vel>
              <min_depth>0</min_depth>
            </ode>
          </contact>
        </surface>
        <laser_retro>0</laser_retro>
      </collision>
      <visual name="wheel_link_fl_geom_visual">
        <pose>0 0 0 0 0 0</pose>
        <geometry>
          <mesh>
            <uri>model://youbot/meshes/base/front-left_wheel.dae</uri>
          </mesh>
        </geometry>
      </visual>
      <gravity>1</gravity>
      <self_collide>0</self_collide>
      <kinematic>0</kinematic>
    </link>
    <link name="caster_link_fr">
      <pose>0.228000 -0.158000 -0.046300 0 0 0</pose>
      <inertial>
        <pose>0 0 0 0 0 0</pose>
        <inertia>
          <ixx>0</ixx>
          <ixy>0</ixy>
          <ixz>0</ixz>
          <iyy>0</iyy>
          <iyz>0</iyz>
          <izz>0</izz>
        </inertia>
        <mass>0.100000</mass>
      </inertial>
      <gravity>1</gravity>
      <self_collide>0</self_collide>
      <kinematic>0</kinematic>
    </link>
    <link name="wheel_link_fr">
      <pose>0.228000 -0.158000 0.046300 0 0 0</pose>
      <inertial>
        <pose>0 0 0 0 0 0</pose>
        <inertia>
          <ixx>0.001480</ixx>
          <ixy>0</ixy>
          <ixz>0</ixz>
          <iyy>0.00175</iyy>
          <iyz>0</iyz>
          <izz>0.001480</izz>
        </inertia>
        <mass>1.400000</mass>
      </inertial>
      <collision name="wheel_link_fr_geom">
        <pose>0 0 0 1.570800 0 0</pose>
        <geometry>
          <cylinder>
            <radius>0.050000</radius>
            <length>0.005000</length>
          </cylinder>
        </geometry>
        <surface>
          <friction>
            <ode>
              <mu>0.5</mu>
              <mu2>0.5</mu2>
              <fdir1>1 0 0</fdir1>
              <slip1>0</slip1>
              <slip2>0</slip2>
            </ode>
          </friction>
          <bounce>
            <restitution_coefficient>0</restitution_coefficient>
            <threshold>0</threshold>
          </bounce>
          <contact>
            <ode>
              <soft_cfm>0</soft_cfm>
              <soft_erp>0.200000</soft_erp>
              <kp>10000000000000.000000</kp>
              <kd>100000000000.000000</kd>
              <max_vel>-1</max_vel>
              <min_depth>0</min_depth>
            </ode>
          </contact>
        </surface>
        <laser_retro>0</laser_retro>
      </collision>
      <visual name="wheel_link_fr_geom_visual">
        <pose>0 0 0 0 0 0</pose>
        <geometry>
          <mesh>
            <uri>model://youbot/meshes/base/front-right_wheel.dae</uri>
          </mesh>
        </geometry>
      </visual>
      <gravity>1</gravity>
      <self_collide>0</self_collide>
      <kinematic>0</kinematic>
    </link>
    <link name="plate_link">
      <pose>-0.159000 0 0.117000 0 0 0</pose>
      <inertial>
        <pose>-0.003761 0 0.007459 0 0 0</pose>
        <inertia>
          <ixx>0.018477</ixx>
          <ixy>0</ixy>
          <ixz>0</ixz>
          <iyy>0.015061</iyy>
          <iyz>0</iyz>
          <izz>0.032539</izz>
        </inertia>
        <mass>2.397</mass>
      </inertial>
      <collision name="plate_link_geom">
        <pose>0 0 0 0 0 0</pose>
        <geometry>
          <mesh>
            <uri>model://youbot/meshes/plate/plate_convex.stl</uri>
          </mesh>
        </geometry>
        <surface>
          <friction>
            <ode>
              <mu>0</mu>
              <mu2>0</mu2>
              <fdir1>0 0 0</fdir1>
              <slip1>0</slip1>
              <slip2>0</slip2>
            </ode>
          </friction>
          <bounce>
            <restitution_coefficient>0</restitution_coefficient>
            <threshold>0</threshold>
          </bounce>
          <contact>
            <ode>
              <soft_cfm>0</soft_cfm>
              <soft_erp>0.200000</soft_erp>
              <kp>10000000000000.000000</kp>
              <kd>100000000000.000000</kd>
              <max_vel>-1</max_vel>
              <min_depth>0</min_depth>
            </ode>
          </contact>
        </surface>
        <laser_retro>0</laser_retro>
      </collision>
      <visual name="plate_link_geom_visual">
        <pose>0 0 0 0 0 0</pose>
        <geometry>
          <mesh>
            <uri>model://youbot/meshes/plate/plate.dae</uri>
          </mesh>
        </geometry>
      </visual>
      <gravity>1</gravity>
      <self_collide>0</self_collide>
      <kinematic>0</kinematic>
    </link>
    <joint name="base_footprint_joint" type="revolute">
      <pose>0 0 0 0 0 0</pose>
      <parent>base_footprint</parent>
      <child>base_link</child>
      <axis>
        <dynamics>
          <damping>0</damping>
          <friction>0</friction>
        </dynamics>
        <limit>
          <lower>0</lower>
          <upper>0</upper>
          <effort>0</effort>
          <velocity>0</velocity>
        </limit>
        <xyz>0 0 1</xyz>
        <use_parent_model_frame>true</use_parent_model_frame>
      </axis>
    </joint>
    <joint name="arm_joint_0" type="revolute">
      <pose>0 0 0 0 0 0</pose>
      <parent>base_link</parent>
      <child>arm_link_0</child>
      <axis>
        <dynamics>
          <damping>0</damping>
          <friction>0</friction>
        </dynamics>
        <limit>
          <lower>0</lower>
          <upper>0</upper>
          <effort>0</effort>
          <velocity>0</velocity>
        </limit>
        <xyz>0 0 1</xyz>
        <use_parent_model_frame>true</use_parent_model_frame>
      </axis>
    </joint>
    <joint name="arm_joint_1" type="revolute">
      <pose>0 0 0 0 0 0</pose>
      <parent>arm_link_0</parent>
      <child>arm_link_1</child>
      <axis>
        <dynamics>
          <damping>0.6</damping>
          <friction>0</friction>
        </dynamics>
        <limit>
          <lower>-2.949606</lower>
          <upper>2.949606</upper>
          <effort>9.5</effort>
          <velocity>2.5</velocity>
        </limit>
        <xyz>0 0 -1</xyz>
        <use_parent_model_frame>true</use_parent_model_frame>
      </axis>
    </joint>
    <joint name="arm_joint_2" type="revolute">
      <pose>0 0 0 0 0 0</pose>
      <parent>arm_link_1</parent>
      <child>arm_link_2</child>
      <axis>
        <dynamics>
          <damping>0.3</damping>
          <friction>0</friction>
        </dynamics>
        <limit>
          <lower>-1.134464</lower>
          <upper>1.570796</upper>
          <effort>9.5</effort>
          <velocity>2.5</velocity>
        </limit>
        <xyz>0 1.000000 0</xyz>
        <use_parent_model_frame>true</use_parent_model_frame>
      </axis>
    </joint>
    <joint name="arm_joint_3" type="revolute">
      <pose>0 0 0 0 0 0</pose>
      <parent>arm_link_2</parent>
      <child>arm_link_3</child>
      <axis>
        <dynamics>
          <damping>0.3</damping>
          <friction>0</friction>
        </dynamics>
        <limit>
          <lower>-2.635447</lower>
          <upper>2.548180</upper>
          <effort>6.0</effort>
          <velocity>2.5</velocity>
        </limit>
        <xyz>0 1.000000 0</xyz>
        <use_parent_model_frame>true</use_parent_model_frame>
      </axis>
    </joint>
    <joint name="arm_joint_4" type="revolute">
      <pose>0 0 0 0 0 0</pose>
      <parent>arm_link_3</parent>
      <child>arm_link_4</child>
      <axis>
        <dynamics>
          <damping>0.3</damping>
          <friction>0</friction>
        </dynamics>
        <limit>
          <lower>-1.788962</lower>
          <upper>1.788962</upper>
          <effort>2.0</effort>
          <velocity>2.5</velocity>
        </limit>
        <xyz>0 1 0</xyz>
        <use_parent_model_frame>true</use_parent_model_frame>
      </axis>
    </joint>
    <joint name="arm_joint_5" type="revolute">
      <pose>0 0 0 0 0 0</pose>
      <parent>arm_link_4</parent>
      <child>arm_link_5</child>
      <axis>
        <dynamics>
          <damping>0.3</damping>
          <friction>0</friction>
        </dynamics>
        <limit>
          <lower>-2.879793</lower>
          <upper>2.879793</upper>
          <effort>1.0</effort>
          <velocity>2.5</velocity>
        </limit>
        <xyz>0 0 -1</xyz>
        <use_parent_model_frame>true</use_parent_model_frame>
      </axis>
    </joint>
    <joint name="gripper_palm_joint" type="revolute">
      <pose>0 0 0 0 0 0</pose>
      <parent>arm_link_5</parent>
      <child>gripper_palm_link</child>
      <axis>
        <dynamics>
          <damping>0</damping>
          <friction>0</friction>
        </dynamics>
        <limit>
          <lower>0</lower>
          <upper>0</upper>
          <effort>0</effort>
          <velocity>0</velocity>
        </limit>
        <xyz>0 0 1</xyz>
        <use_parent_model_frame>true</use_parent_model_frame>
      </axis>
    </joint>
    <joint name="gripper_finger_joint_l" type="prismatic">
      <pose>0 0 0 0 0 0</pose>
      <parent>gripper_palm_link</parent>
      <child>gripper_finger_link_l</child>
      <axis>
        <dynamics>
          <damping>1</damping>
          <friction>0</friction>
        </dynamics>
        <limit>
          <lower>0</lower>
          <upper>0.0082</upper>
          <effort>0.5</effort>
          <velocity>0.1</velocity>
        </limit>
        <xyz>0 1 0</xyz>
        <use_parent_model_frame>true</use_parent_model_frame>
      </axis>
    </joint>
    <joint name="gripper_finger_joint_r" type="prismatic">
      <pose>0 0 0 0 0 0</pose>
      <parent>gripper_palm_link</parent>
      <child>gripper_finger_link_r</child>
      <axis>
        <dynamics>
          <damping>10</damping>
          <friction>0</friction>
        </dynamics>
        <limit>
          <lower>-0.0082</lower>
          <upper>0</upper>
          <effort>0.5</effort>
          <velocity>0.1</velocity>
        </limit>
        <xyz>0 1 0</xyz>
        <use_parent_model_frame>true</use_parent_model_frame>
      </axis>
    </joint>
    <joint name="base_laser_front_hokuyo_urg04_laser_joint" type="revolute">
      <pose>0 0 0 0 0 0</pose>
      <parent>base_link</parent>
      <child>base_laser_front_link</child>
      <axis>
        <dynamics>
          <damping>0</damping>
          <friction>0</friction>
        </dynamics>
        <limit>
          <lower>0</lower>
          <upper>0</upper>
          <effort>0</effort>
          <velocity>0</velocity>
        </limit>
        <xyz>0 0 1</xyz>
        <use_parent_model_frame>true</use_parent_model_frame>
      </axis>
    </joint>
    <joint name="caster_joint_bl" type="revolute">
      <pose>0 0 0 0 0 0</pose>
      <parent>base_link</parent>
      <child>caster_link_bl</child>
      <axis>
        <dynamics>
          <damping>1</damping>
          <friction>0</friction>
        </dynamics>
        <limit>
          <lower>0</lower>
          <upper>0</upper>
          <effort>0</effort>
          <velocity>0</velocity>
        </limit>
        <xyz>0 0 1</xyz>
        <use_parent_model_frame>true</use_parent_model_frame>
      </axis>
    </joint>
    <joint name="wheel_joint_bl" type="revolute">
      <pose>0 0 0 0 0 0</pose>
      <parent>caster_link_bl</parent>
      <child>wheel_link_bl</child>
      <axis>
        <dynamics>
          <damping>1</damping>
          <friction>0</friction>
        </dynamics>
        <limit>
          <lower>-10000000000000000.000000</lower>
          <upper>10000000000000000.000000</upper>
          <effort>12</effort>
          <velocity>16</velocity>
        </limit>
        <xyz>0 1.000000 0</xyz>
        <use_parent_model_frame>true</use_parent_model_frame>
      </axis>
    </joint>
    <joint name="caster_joint_br" type="revolute">
      <pose>0 0 0 0 0 0</pose>
      <parent>base_link</parent>
      <child>caster_link_br</child>
      <axis>
        <dynamics>
          <damping>1</damping>
          <friction>0</friction>
        </dynamics>
        <limit>
          <lower>0</lower>
          <upper>0</upper>
          <effort>0</effort>
          <velocity>0</velocity>
        </limit>
        <xyz>0 0 1</xyz>
        <use_parent_model_frame>true</use_parent_model_frame>
      </axis>
    </joint>
    <joint name="wheel_joint_br" type="revolute">
      <pose>0 0 0 0 0 0</pose>
      <parent>caster_link_br</parent>
      <child>wheel_link_br</child>
      <axis>
        <dynamics>
          <damping>1</damping>
          <friction>0</friction>
        </dynamics>
        <limit>
          <lower>-10000000000000000.000000</lower>
          <upper>10000000000000000.000000</upper>
          <effort>12</effort>
          <velocity>16</velocity>
        </limit>
        <xyz>0 1.000000 0</xyz>
        <use_parent_model_frame>true</use_parent_model_frame>
      </axis>
    </joint>
    <joint name="caster_joint_fl" type="revolute">
      <pose>0 0 0 0 0 0</pose>
      <parent>base_link</parent>
      <child>caster_link_fl</child>
      <axis>
        <dynamics>
          <damping>1</damping>
          <friction>0</friction>
        </dynamics>
        <limit>
          <lower>0</lower>
          <upper>0</upper>
          <effort>0</effort>
          <velocity>0</velocity>
        </limit>
        <xyz>0 0 1</xyz>
        <use_parent_model_frame>true</use_parent_model_frame>
      </axis>
    </joint>
    <joint name="wheel_joint_fl" type="revolute">
      <pose>0 0 0 0 0 0</pose>
      <parent>caster_link_fl</parent>
      <child>wheel_link_fl</child>
      <axis>
        <dynamics>
          <damping>1</damping>
          <friction>0</friction>
        </dynamics>
        <limit>
          <lower>-10000000000000000.000000</lower>
          <upper>10000000000000000.000000</upper>
          <effort>12</effort>
          <velocity>16</velocity>
        </limit>
        <xyz>0 1.000000 0</xyz>
        <use_parent_model_frame>true</use_parent_model_frame>
      </axis>
    </joint>
    <joint name="caster_joint_fr" type="revolute">
      <pose>0 0 0 0 0 0</pose>
      <parent>base_link</parent>
      <child>caster_link_fr</child>
      <axis>
        <dynamics>
          <damping>1</damping>
          <friction>0</friction>
        </dynamics>
        <limit>
          <lower>0</lower>
          <upper>0</upper>
          <effort>0</effort>
          <velocity>0</velocity>
        </limit>
        <xyz>0 0 1</xyz>
        <use_parent_model_frame>true</use_parent_model_frame>
      </axis>
    </joint>
    <joint name="wheel_joint_fr" type="revolute">
      <pose>0 0 0 0 0 0</pose>
      <parent>caster_link_fr</parent>
      <child>wheel_link_fr</child>
      <axis>
        <dynamics>
          <damping>1</damping>
          <friction>0</friction>
        </dynamics>
        <limit>
          <lower>-10000000000000000.000000</lower>
          <upper>10000000000000000.000000</upper>
          <effort>12</effort>
          <velocity>16</velocity>
        </limit>
        <xyz>0 1.000000 0</xyz>
        <use_parent_model_frame>true</use_parent_model_frame>
      </axis>
    </joint>
    <joint name="plate_joint" type="revolute">
      <parent>base_link</parent>
      <child>plate_link</child>
      <axis>
        <dynamics>
          <damping>0</damping>
          <friction>0</friction>
        </dynamics>
        <limit>
          <lower>0</lower>
          <upper>0</upper>
          <effort>0</effort>
          <velocity>0</velocity>
        </limit>
        <xyz>0 0 1</xyz>
        <use_parent_model_frame>true</use_parent_model_frame>
      </axis>
    </joint>
    <static>0</static>
  </model>
</sdf>
